<?xml version='1.0'?>

<robot name="slam_bot" xmlns:xacro="http://www.ros.org/wiki/xacro">

<xacro:include filename="$(find slam_project)/urdf/slam_bot.gazebo"/>

        <material name="blue">
         <color rgba="0 0 0.8 1"/>
        </material>

        <material name="black">
         <color rgba="0 0 0 1"/>
        </material>

        <material name="red">
         <color rgba="0.8 0 0 1"/>
        </material>

        <material name="white">
         <color rgba="1 1 1 1"/>
        </material>

  <link name="robot_footprint"></link>

      <joint name="robot_footprint_joint" type="fixed">
        <origin xyz="0 0 0" rpy="0 0 0" />
        <parent link="robot_footprint"/>
        <child link="chassis" />
      </joint>

  <link name='chassis'>
    <pose>0 0 0.1 0 0 0</pose>

        <inertial>
            <mass value="15.0"/>
            <origin xyz="0.0 0 0" rpy=" 0 0 0"/>
            <inertia
                ixx="0.1" ixy="0" ixz="0"
                iyy="0.1" iyz="0"
                izz="0.1"
            />
        </inertial>

        <collision name='collision'>
            <origin xyz="0 0 0" rpy=" 0 0 0"/> 
            <geometry>
              <box size=".4 .2 .1"/>
            </geometry>
        </collision>

        <visual>
            <origin xyz="0 0 0" rpy=" 0 0 0"/>
            <geometry>
              <box size=".4 .2 .1"/>
            </geometry>
                <material name="blue"/>
        </visual>


        <collision name='back_caster_collision'>
          <origin xyz="-0.15 0 -0.05" rpy=" 0 0 0"/>
          <geometry>
            <sphere radius="0.05"/>
          </geometry>
          <surface>
            <friction>
              <ode>
                <mu>0</mu>
                <mu2>0</mu2>
                <slip1>1.0</slip1>
                <slip2>1.0</slip2>
              </ode>
            </friction>
          </surface>
        </collision>

        <visual name='back_caster_visual'>
          <origin xyz="-0.15 0 -0.05" rpy=" 0 0 0"/>
          <geometry>
            <sphere radius="0.05"/>
          </geometry>
        </visual>

        <collision name='front_caster_collision'>
          <origin xyz="0.15 0 -0.05" rpy=" 0 0 0"/>
          <geometry>
            <sphere radius="0.05"/>
          </geometry>
          <surface>
            <friction>
              <ode>
                <mu>0</mu>
                <mu2>0</mu2>
                <slip1>1.0</slip1>
                <slip2>1.0</slip2>
              </ode>
            </friction>
          </surface>
        </collision>

        <visual>
          <origin xyz="0.15 0 -0.05" rpy=" 0 0 0"/>
          <geometry>
            <sphere radius="0.05"/>
          </geometry>
        </visual>

  </link>

    <link name="wheel_right_link">
      <visual>
        <origin rpy="0 1.5707 1.5707" xyz="0 0 0"/>
        <geometry>
          <cylinder length="0.05" radius="0.1"/>
        </geometry>
        <material name="white"/>
      </visual>

      <inertial>
            <mass value="5.0"/>
            <origin rpy="0 1.5707 1.5707" xyz="0 0 0"/>
            <inertia
                ixx="0.1" ixy="0" ixz="0"
                iyy="0.1" iyz="0"
                izz="0.1"
            />
      </inertial>

        <collision name='col_right_wheel'>
            <origin rpy="0 1.5707 1.5707" xyz="0 0 0"/> 
            <geometry>
              <cylinder length="0.05" radius="0.1"/>
            </geometry>
        </collision>

    </link>

 

   <link name="wheel_left_link">
     <visual>
       <origin rpy="0 1.5707 1.5707" xyz="0 0 0"/>

       <geometry>
         <cylinder length="0.05" radius="0.1"/>
       </geometry>
       <material name="black"/>
      
     </visual>

      <inertial>
            <mass value="5.0"/>
            <origin rpy="0 1.5707 1.5707" xyz="0 0 0"/>
            <inertia
                ixx="0.1" ixy="0" ixz="0"
                iyy="0.1" iyz="0"
                izz="0.1"
            />
      </inertial>

        <collision name='col_left_wheel'>
            <origin rpy="0 1.5707 1.5707" xyz="0 0 0"/> 
            <geometry>
              <cylinder length="0.05" radius="0.1"/>
            </geometry>
        </collision>

   </link>

   <link name="camera_link">

   <imageTopicName>/rgb/image_raw</imageTopicName>

     <visual>
       <origin rpy="0 0 0" xyz="0 0 0"/>

       <geometry>
         <box size="0.05 0.05 0.05"/>
       </geometry>
       <material name="red"/>
     </visual>

      <inertial>
            <mass value="0.1"/>
            <origin rpy="0 0 0" xyz="0 0 0"/>
            <inertia
                ixx="0.1" ixy="0" ixz="0"
                iyy="0.1" iyz="0"
                izz="0.1"
            />
      </inertial>

        <collision name='col_camera'>
            <origin rpy="0 0 0" xyz="0 0 0"/> 
            <geometry>
              <box size="0.05 0.05 0.05"/>
            </geometry>
        </collision>

    </link> 


   <joint name="camera_joint" type="fixed">
      
      <parent link="chassis"/>

      <child link="camera_link"/>

      <origin rpy="0 0 0" xyz="0.2 0 0"/>

   </joint>

   <link name="camera_rgbd_frame">

   <imageTopicName>/camera_rgbd_frame</imageTopicName>

     <visual>
       <origin rpy="0 0 0" xyz="0 0 0"/>

       <geometry>
         <box size="0.05 0.05 0.05"/>
       </geometry>
       <material name="green"/>
     </visual>

      <inertial>
            <mass value="0.01"/>
            <origin rpy="0 0 0" xyz="0 0 0"/>
            <inertia
                ixx="0.01" ixy="0" ixz="0"
                iyy="0.01" iyz="0"
                izz="0.01"
            />
      </inertial>

        <collision name='col_rgbd'>
            <origin rpy="0 0 0" xyz="0 0 0"/> 
            <geometry>
              <box size="0.05 0.05 0.05"/>
            </geometry>
        </collision>

    </link> 


   <joint name="camera_rgbd_joint" type="fixed">
      
      <parent link="camera_link"/>

      <child link="camera_rgbd_frame"/>

      <origin rpy="0 0 0" xyz="0.2 0 0"/>

   </joint>

   <link name="hokuyo">
      <topicName>/scan</topicName>

     <visual>
       <origin rpy="0 0 0" xyz="0 0 0"/>
       <geometry>
         <mesh filename="package://slam_project/meshes/hokuyo.dae"/>
       </geometry>   
     </visual>

      <inertial>
            <mass value="0.1"/>
            <origin rpy="0 0 0" xyz="0 0 0"/>
            <inertia
                ixx="0.1" ixy="0" ixz="0"
                iyy="0.1" iyz="0"
                izz="0.1"
            />
      </inertial>

        <collision name='col_hokuyo'>
            <origin rpy="0 0 0" xyz="0 0 0"/> 
            <geometry>
              <mesh filename="package://slam_project/meshes/hokuyo.dae"/>
            </geometry>
        </collision>
    
    </link>


   <joint name="hokuyo_joint" type="fixed">
       
      <parent link="chassis"/>

      <child link="hokuyo"/>

      <origin rpy="0 0 0" xyz="0.15 0 0.15"/>

      <axis xyz="0 0 1" rpy="0 0 0"/>

   </joint>

   

    <joint name="right_wheel_hinge" type="continuous">
      
      <parent link="chassis"/>
      
      <child link="wheel_right_link"/>

      <origin rpy="0 0 0" xyz="0 -0.15 0"/>
      
      <axis xyz="0 1 0" rpy="0 0 0"/>

      <limit effort="10000" velocity="1000"/>
      
      <joint_properties damping="1.0" friction="1.0"/>

   </joint>


   <joint name="left_wheel_hinge" type="continuous">
      
      <parent link="chassis"/>
      
      <child link="wheel_left_link"/>

      <origin rpy="0 0 0" xyz="0 0.15 0"/>
      
      <axis xyz="0 1 0" rpy="0 0 0"/>

      <limit effort="10000" velocity="1000"/>
      
      <joint_properties damping="1.0" friction="1.0"/>

   </joint>
 



</robot>

